[2025-05-24 17:49:47 +0000] [1884] [INFO] Starting gunicorn 23.0.0
[2025-05-24 17:49:47 +0000] [1884] [INFO] Listening at: http://0.0.0.0:5000 (1884)
[2025-05-24 17:49:47 +0000] [1884] [INFO] Using worker: sync
[2025-05-24 17:49:47 +0000] [1895] [INFO] Booting worker with pid: 1895
[2025-05-24 17:49:48 +0000] [1884] [INFO] Handling signal: winch
[2025-05-24 17:49:48 +0000] [1884] [INFO] Handling signal: winch
[2025-05-24 17:49:48 +0000] [1895] [ERROR] Exception in worker process
Traceback (most recent call last):
  File "/home/runner/workspace/.pythonlibs/lib/python3.12/site-packages/gunicorn/arbiter.py", line 608, in spawn_worker
    worker.init_process()
  File "/home/runner/workspace/.pythonlibs/lib/python3.12/site-packages/gunicorn/workers/base.py", line 135, in init_process
    self.load_wsgi()
  File "/home/runner/workspace/.pythonlibs/lib/python3.12/site-packages/gunicorn/workers/base.py", line 147, in load_wsgi
    self.wsgi = self.app.wsgi()
                ^^^^^^^^^^^^^^^
  File "/home/runner/workspace/.pythonlibs/lib/python3.12/site-packages/gunicorn/app/base.py", line 66, in wsgi
    self.callable = self.load()
                    ^^^^^^^^^^^
  File "/home/runner/workspace/.pythonlibs/lib/python3.12/site-packages/gunicorn/app/wsgiapp.py", line 57, in load
    return self.load_wsgiapp()
           ^^^^^^^^^^^^^^^^^^^
  File "/home/runner/workspace/.pythonlibs/lib/python3.12/site-packages/gunicorn/app/wsgiapp.py", line 47, in load_wsgiapp
    return util.import_app(self.app_uri)
           ^^^^^^^^^^^^^^^^^^^^^^^^^^^^^
  File "/home/runner/workspace/.pythonlibs/lib/python3.12/site-packages/gunicorn/util.py", line 370, in import_app
    mod = importlib.import_module(module)
          ^^^^^^^^^^^^^^^^^^^^^^^^^^^^^^^
  File "/nix/store/nb21sc3npfc8gvazwnrjxpvb5d48jysx-python3-3.12.7/lib/python3.12/importlib/__init__.py", line 90, in import_module
    return _bootstrap._gcd_import(name[level:], package, level)
           ^^^^^^^^^^^^^^^^^^^^^^^^^^^^^^^^^^^^^^^^^^^^^^^^^^^^
  File "<frozen importlib._bootstrap>", line 1387, in _gcd_import
  File "<frozen importlib._bootstrap>", line 1360, in _find_and_load
  File "<frozen importlib._bootstrap>", line 1331, in _find_and_load_unlocked
  File "<frozen importlib._bootstrap>", line 935, in _load_unlocked
  File "<frozen importlib._bootstrap_external>", line 995, in exec_module
  File "<frozen importlib._bootstrap>", line 488, in _call_with_frames_removed
  File "/home/runner/workspace/app.py", line 18, in <module>
    from utils.analysis import check_analysis_in_progress, perform_analysis
  File "/home/runner/workspace/utils/analysis.py", line 5, in <module>
    from engines import (
ImportError: cannot import name 'opencti' from 'engines' (/home/runner/workspace/engines/__init__.py)
[2025-05-24 17:49:48 +0000] [1895] [INFO] Worker exiting (pid: 1895)
[2025-05-24 17:49:48 +0000] [1884] [INFO] Handling signal: winch
[2025-05-24 17:49:48 +0000] [1884] [INFO] Handling signal: winch
[2025-05-24 17:49:48 +0000] [1884] [ERROR] Worker (pid:1895) exited with code 3
[2025-05-24 17:49:48 +0000] [1884] [ERROR] Shutting down: Master
[2025-05-24 17:49:48 +0000] [1884] [ERROR] Reason: Worker failed to boot.